Workbook

Sheet Guide
B1: ATS Weekly Data – User Guide
B2: One workbook, filled once a week, feeds BOTH the Weekly Report and the Monthly Council dashboard.
B3: SAMPLE DATA – fictional illustrative history for this portfolio; replace before presenting
B4: Data Mode on the Config sheet = SAMPLE. The history in this file is made up so you can try the dashboard. Replace it with your own rows, then set Data Mode to LIVE.
B6: 1. The idea: fill once, weekly
B7: • Every Friday you add ONE new row to Weekly_Snapshot and one row per active topic to Topic_Progress and Readiness; defects, TSRs and milestones are updated whenever they change. Nothing is ever overwritten: history is kept as dated rows.
B8: • A WEEK is a slice (the latest Week Ending). A MONTH or QUARTER is a roll-up of the weeks in it (see section 4). That is how the same file feeds the Weekly Report and the Monthly Council.
B9: • Yellow cells (blue text) are for you to type or pick from a dropdown. Grey cells are formulas – never type over them. Dates are real dates shown as yyyy-mm-dd; use Alt+Enter for a new line inside a text cell.
B10: • Do not rename sheets, rename or reorder column headers, or insert columns: the dashboard finds columns by header text. Adding new rows below the last row is always safe (about 300 rows are pre-formatted on each data sheet).
B12: 2. What to update and when
B13: When | C13: Sheet | D13: What to do | E13: Rows
B14: Weekly (every Friday) | C14: Weekly_Snapshot | D14: Add 1 new row for the new Week Ending (a Friday). Enter cumulative-to-date counts, test days, downtime hours, FTE, spend and the Overall RAG + summary. | E14: 1 per week
B15: Weekly | C15: Topic_Progress | D15: 1 row per active topic: phase, test cases planned / designed, and cumulative passed, failed, blocked. | E15: 1 per topic per week
B16: Weekly | C16: Defect_Log | D16: Add new defects; update Status, Resolved Date, TCs Blocked and Triage Comments on existing ones. | E16: As needed
B17: Weekly | C17: Readiness | D17: 1 row per topic: planned SIT start, overall RAG, six readiness areas (RAG + note) and Road to Green. | E17: 1 per topic per week
B18: Weekly (optional) | C18: Commentary | D18: Narrative per KPI for the week: highlights, concern, actions, executive commentary; optional RAG / current-position override. | E18: 0–16 per week
B19: As they happen | C19: TSR_Log | D19: Add a TSR when received; fill Returned Date when sent back and Hold Days for time pending clarification. | E19: 1 per TSR
B20: As they happen | C20: Milestones | D20: Add each milestone once. Set Forecast Date if it slips and Completed Date when done. | E20: 1 per milestone
B21: As they happen | C21: Defect_Log | D21: Raise a defect the day it is logged; set Resolved Date when fix + confirmation test is complete (or on rejection). | E21: 1 per defect
B22: Monthly / Quarterly | C22: Weekly_Snapshot (CSAT columns) | D22: Enter the CSAT score and number of responses only in the week a survey result is received; otherwise leave blank (= 'Not Requested'). | E22: Occasional
B23: Monthly / Quarterly | C23: Demand_Forecast | D23: Refresh planned vs available FTE for the coming months. | E23: 1 per month
B24: Monthly / Quarterly | C24: Lessons_Learned | D24: Record lessons and improvement actions; update Status when actioned. | E24: As needed
... B26: Yearly / rarely | C26: Bank_Holidays, Config, Lists | D26: Extend bank holidays each year; change RAG thresholds or add dropdown values (Lists) only when the rules change. | E26: Rare
B28: 3. Colour legend
B29: Sample | C29: Input cell (yellow, blue) | D29: Type here or pick from the dropdown.
B30: Sample | C30: Calculated cell (grey) | D30: Formula – never type over it.
B31: Sample | C31: EXAMPLE row (grey italic) | D31: Delete it; the dashboard ignores rows whose Notes start with EXAMPLE.
B32: Green | C32: Green | D32: On track / within target.
B33: Amber | C33: Amber | D33: At risk / watch closely.
B34: Red | C34: Red | D34: Off track / action needed.
B36: 4. Flow vs cumulative: how weeks roll up into a month or quarter
B37: Type | C37: Measures | D37: Roll-up rule | E37: Why
B38: FLOW measures | C38: Planned Test Days, Downtime Hours | D38: SUM over the weeks in the period. | E38: Each week records only what happened that week.
B39: CUMULATIVE / snapshot measures | C39: Coverage, automation, test execution (passed / failed / blocked, designed), resources, cumulative spend, forecast at completion | D39: Take the LATEST week in the period. | E39: Each week records the running total to date, so the last week already contains everything before it.
B40: Example: September availability = 1 − (sum of September downtime hours) ÷ (sum of September planned test days × hours per test day). Coverage for September = the value in the last September week.
B42: 5. RAG rules the dashboard applies (thresholds live on the Config sheet)
B43: KPI | C43: Rule | E43: Source
B44: Risk Based Coverage | C44: Per risk level: coverage = Covered ÷ Requirements; Green ≥ target, Amber ≥ target − tolerance, else Red. Overall = worst of High and Medium. | E44: ATS KPI Data Collation – M.Coverage (3.9)
B45: Production Defect Leakage (quarterly) | C45: Defects with Found In = Production in the quarter to date. Red if P1 ≥ 1 or P2 ≥ 5 or P3 ≥ 6; Amber if P2 in 1–4 or P3 in 1–5; else Green. 'Not in Production' while Go-Live is blank. | E45: Q.Defects (3.1)
B46: Defect Detection Effectiveness | C46: DDE = Testing-found ÷ (Testing-found + Production-found). Also raised / rejected by priority; rejection % Green ≤ 5%, Amber ≤ 10%, else Red. | E46: M.Defects (3.2)
...

Sheet Config
A1: Config – programme details, thresholds and rules
A2: Keys in column A are read by the dashboard (text must not change); edit only the yellow values in column B.
A3: SAMPLE DATA – fictional illustrative history for this portfolio; replace before presenting
A4: Setting | B4: Value | C4: Description / assumption
A5: Program Name | B5: HMRC ATS – Self Assessment | C5: Shown in dashboard headers. SAMPLE – fictional value.
A6: Project / Phase | B6: Phase 1 | C6: SAMPLE – fictional value for this portfolio.
A7: TSR Reference | B7: TSR_PR021877-REQ031204 | C7: The portfolio's own TSR (QA activities and resource estimation). SAMPLE – dummy reference.
A8: Programme Test Manager | B8: TBC | C8: SAMPLE – name left as TBC.
A9: Test Manager | B9: TBC | C9: SAMPLE – name left as TBC.
A10: Programme Start Date | B10: 46083 | C10: SAMPLE – fictional date.
A11: Programme End Date | B11: 46374 | C11: Programme end date as supplied by the test-delivery lead.
A12: Total Budget (£) | B12: 760000 | C12: SAMPLE – fictional budget scaled to the portfolio's size.
A13: Production Go-Live Date | C13: Leave BLANK until the solution is live in production. Blank = 'Not in Production' (Production Defect Leakage is not scored).
A14: Data Mode | B14: SAMPLE | C14: SAMPLE DATA – fictional illustrative history for this portfolio; replace before presenting. SAMPLE = seeded demo data; LIVE = real data. The dashboard shows a SAMPLE badge when this says SAMPLE. Change to LIVE once you replace the sample rows with real ones.
A15: Hours per Test Day | B15: 8 | C15: Source: ATS KPI Data Collation – M.Downtime (4.14): Required Hours = test days x 8.
A16: TSR SLA – Max Working Days | B16: 10 | C16: Source: ATS KPI Data Collation – M.TSR Assessment (3.5): Red if any TSR working days > 10.
A17: Defect Turnaround SLA – Working Days | B17: 5 | C17: Source: M.Defect Turnaround (4.11) ageing buckets (0-2, 3-5, 6-10, >10 days). ASSUMPTION: not defined in the source KPI workbook; 5 working days is used as the SLA.
A18: Defect Turnaround – Green if SLA compliance >= | B18: 0.8 | C18: ASSUMPTION – not defined in the source KPI workbook; turnaround RAG thresholds (share of defects resolved within SLA).
A19: Defect Turnaround – Amber if SLA compliance >= | B19: 0.6 | C19: ASSUMPTION – not defined in the source KPI workbook; turnaround RAG thresholds (share of defects resolved within SLA).
A20: Defect Rejection – Green if <= | B20: 0.05 | C20: Source: ATS KPI Data Collation – M.Defects (3.2): Green if rejection <= 5%.
A21: Defect Rejection – Amber if <= | B21: 0.1 | C21: Source: ATS KPI Data Collation – M.Defects (3.2): Amber if rejection <= 10%, else Red.
A22: Downtime (monthly) – Green if hours <= | B22: 24 | C22: Source: ATS KPI Data Collation – M.Downtime (4.14).
A23: Downtime (monthly) – Amber if hours <= | B23: 48 | C23: Source: ATS KPI Data Collation – M.Downtime (4.14); above this = Red.
A24: Downtime (weekly) – Green if hours <= | B24: 6 | C24: ASSUMPTION – not defined in the source KPI workbook; weekly downtime thresholds (monthly thresholds scaled to a week).
A25: Downtime (weekly) – Amber if hours <= | B25: 12 | C25: ASSUMPTION – not defined in the source KPI workbook; weekly downtime thresholds; above this = Red.
A26: Coverage Target – High Risk | B26: 0.98 | C26: Source: ATS KPI Data Collation – M.Coverage (3.9).
... A37: Commercial – Amber if forecast <= budget + (share) | B37: 0.05 | C37: ASSUMPTION – not defined in the source KPI workbook; commercial RAG: Green <= budget, Amber <= budget + this share, else Red.
A38: Portfolio Name | B38: Self Assessment | C38: The name this portfolio is shown under in the dashboard's portfolio dropdown and cross-portfolio overview. Must be unique across portfolios.
A39: Programme | B39: HMRC ATS | C39: Groups portfolios under one programme heading.

Sheet Weekly_Snapshot
A1: Weekly_Snapshot [SAMPLE DATA – illustrative]
A2: One row per week: environment, coverage, automation, satisfaction, resourcing & commercials and the overall RAG. Coverage / automation / resources / spend are CUMULATIVE to date.
A3: HOW TO FILL: add ONE new row each Friday (new Week Ending). Yellow = type; grey = formula. Leave CSAT blank unless a score was collected that week.
A4: WEEK | B4: ENVIRONMENT | E4: COVERAGE | Q4: AUTOMATION | W4: SATISFACTION | Y4: RESOURCING & COMMERCIALS | AC4: OVERALL
A5: Week Ending | B5: Planned Test Days | C5: Downtime Hours | D5: Availability % | E5: High Risk – Requirements | F5: High Risk – Test Cases | G5: High Risk – Covered Reqs | H5: High Risk – Coverage % | I5: Medium Risk – Requirements | J5: Medium Risk – Test Cases | K5: Medium Risk – Covered Reqs | L5: Medium Risk – Coverage % | M5: Low Risk – Requirements | N5: Low Risk – Test Cases | O5: Low Risk – Covered Reqs | P5: Low Risk – Coverage % | Q5: Automatable Test Data Setups | R5: Automated Test Data Setups | S5: Test Data Automation % | T5: Automatable Test Cases | U5: Automated Test Cases | V5: Test Case Automation % | W5: CSAT Score (1-5) | X5: CSAT Responses | Y5: Resources Planned (FTE) | Z5: Resources Actual (FTE) | AA5: Cumulative Spend (£) | AB5: Forecast at Completion (£) | AC5: Overall RAG | AD5: Overall Executive Summary | AE5: Notes
A6: 46213 | B6: 5 | C6: 0 | D6: =IF(N(B6)>0,1-N(C6)/(B6*Config!$B$15),"") -> 1 | E6: 72 | F6: 25 | G6: 25 | H6: =IF(AND(ISNUMBER(E6),E6>0),N(G6)/E6,"") -> 0.34722222 | I6: 100 | J6: 29 | K6: 29 | L6: =IF(AND(ISNUMBER(I6),I6>0),N(K6)/I6,"") -> 0.29 | M6: 48 | N6: 10 | O6: 10 | P6: =IF(AND(ISNUMBER(M6),M6>0),N(O6)/M6,"") -> 0.20833333 | Q6: 150 | R6: 40 | S6: =IF(AND(ISNUMBER(Q6),Q6>0),N(R6)/Q6,"") -> 0.26666667 | T6: 200 | U6: 60 | V6: =IF(AND(ISNUMBER(T6),T6>0),N(U6)/T6,"") -> 0.3 | Y6: 6 | Z6: 6 | AA6: 465000 | AB6: 760000 | AC6: Green | AD6: Portfolio mobilised for the autumn releases; test approach re-baselined and Release 1 design under way. Cumulative execution: 0 of 420 test cases (0%); 0 blocked; 0 open defects.
A7: 46220 | B7: 5 | C7: 1 | D7: =IF(N(B7)>0,1-N(C7)/(B7*Config!$B$15),"") -> 0.975 | E7: 72 | F7: 34 | G7: 34 | H7: =IF(AND(ISNUMBER(E7),E7>0),N(G7)/E7,"") -> 0.47222222 | I7: 100 | J7: 41 | K7: 41 | L7: =IF(AND(ISNUMBER(I7),I7>0),N(K7)/I7,"") -> 0.41 | M7: 48 | N7: 14 | O7: 14 | P7: =IF(AND(ISNUMBER(M7),M7>0),N(O7)/M7,"") -> 0.29166667 | Q7: 150 | R7: 46 | S7: =IF(AND(ISNUMBER(Q7),Q7>0),N(R7)/Q7,"") -> 0.30666667 | T7: 200 | U7: 68 | V7: =IF(AND(ISNUMBER(T7),T7>0),N(U7)/T7,"") -> 0.34 | Y7: 6 | Z7: 6 | AA7: 477000 | AB7: 760000 | AC7: Green | AD7: Release 1 test design progressing; requirements walk-throughs complete. Cumulative execution: 0 of 420 test cases (0%); 0 blocked; 0 open defects.
A8: 46227 | B8: 5 | C8: 0 | D8: =IF(N(B8)>0,1-N(C8)/(B8*Config!$B$15),"") -> 1 | E8: 72 | F8: 42 | G8: 42 | H8: =IF(AND(ISNUMBER(E8),E8>0),N(G8)/E8,"") -> 0.58333333 | I8: 100 | J8: 52 | K8: 52 | L8: =IF(AND(ISNUMBER(I8),I8>0),N(K8)/I8,"") -> 0.52 | M8: 48 | N8: 25 | O8: 17 | P8: =IF(AND(ISNUMBER(M8),M8>0),N(O8)/M8,"") -> 0.35416667 | Q8: 150 | R8: 51 | S8: =IF(AND(ISNUMBER(Q8),Q8>0),N(R8)/Q8,"") -> 0.34 | T8: 200 | U8: 75 | V8: =IF(AND(ISNUMBER(T8),T8>0),N(U8)/T8,"") -> 0.375 | Y8: 6 | Z8: 6 | AA8: 488000 | AB8: 760000 | AC8: Green | AD8: Release 2 design started; test data set-up scripted. Cumulative execution: 0 of 420 test cases (0%); 0 blocked; 0 open defects.
A9: 46234 | B9: 5 | C9: 0 | D9: =IF(N(B9)>0,1-N(C9)/(B9*Config!$B$15),"") -> 1 | E9: 72 | F9: 50 | G9: 49 | H9: =IF(AND(ISNUMBER(E9),E9>0),N(G9)/E9,"") -> 0.68055556 | I9: 100 | J9: 75 | K9: 62 | L9: =IF(AND(ISNUMBER(I9),I9>0),N(K9)/I9,"") -> 0.62 | M9: 48 | N9: 41 | O9: 20 | P9: =IF(AND(ISNUMBER(M9),M9>0),N(O9)/M9,"") -> 0.41666667 | Q9: 150 | R9: 57 | S9: =IF(AND(ISNUMBER(Q9),Q9>0),N(R9)/Q9,"") -> 0.38 | T9: 200 | U9: 82 | V9: =IF(AND(ISNUMBER(T9),T9>0),N(U9)/T9,"") -> 0.41 | Y9: 6 | Z9: 6 | AA9: 500000 | AB9: 760000 | AC9: Green | AD9: Smoke scripts ready and entry criteria agreed. Cumulative execution: 0 of 420 test cases (0%); 0 blocked; 0 open defects.
A10: 46241 | B10: 5 | C10: 1 | D10: =IF(N(B10)>0,1-N(C10)/(B10*Config!$B$15),"") -> 0.975 | E10: 72 | F10: 71 | G10: 55 | H10: =IF(AND(ISNUMBER(E10),E10>0),N(G10)/E10,"") -> 0.76388889 | I10: 100 | J10: 107 | K10: 72 | L10: =IF(AND(ISNUMBER(I10),I10>0),N(K10)/I10,"") -> 0.72 | M10: 48 | N10: 59 | O10: 23 | P10: =IF(AND(ISNUMBER(M10),M10>0),N(O10)/M10,"") -> 0.47916667 | Q10: 150 | R10: 63 | S10: =IF(AND(ISNUMBER(Q10),Q10>0),N(R10)/Q10,"") -> 0.42 | T10: 200 | U10: 90 | V10: =IF(AND(ISNUMBER(T10),T10>0),N(U10)/T10,"") -> 0.45 | Y10: 6 | Z10: 6 | AA10: 513000 | AB10: 760000 | AC10: Green | AD10: Smoke testing complete; SIT execution started for Release 1. First defect fixed within 2 days. Cumulative execution: 13 of 420 test cases (3%); 0 blocked; 0 open defects.
A11: 46248 | B11: 5 | C11: 0 | D11: =IF(N(B11)>0,1-N(C11)/(B11*Config!$B$15),"") -> 1 | E11: 72 | F11: 87 | G11: 60 | H11: =IF(AND(ISNUMBER(E11),E11>0),N(G11)/E11,"") -> 0.83333333 | I11: 100 | J11: 130 | K11: 79 | L11: =IF(AND(ISNUMBER(I11),I11>0),N(K11)/I11,"") -> 0.79 | M11: 48 | N11: 72 | O11: 25 | P11: =IF(AND(ISNUMBER(M11),M11>0),N(O11)/M11,"") -> 0.52083333 | Q11: 150 | R11: 69 | S11: =IF(AND(ISNUMBER(Q11),Q11>0),N(R11)/Q11,"") -> 0.46 | T11: 200 | U11: 98 | V11: =IF(AND(ISNUMBER(T11),T11>0),N(U11)/T11,"") -> 0.49 | Y11: 6 | Z11: 5 | AA11: 525000 | AB11: 760000 | AC11: Green | AD11: SIT execution progressing; one team member on leave, no schedule impact. Cumulative execution: 26 of 420 test cases (6%); 0 blocked; 0 open defects. | AE11: One FTE on leave this week.
A12: 46255 | B12: 5 | C12: 1 | D12: =IF(N(B12)>0,1-N(C12)/(B12*Config!$B$15),"") -> 0.975 | E12: 72 | F12: 98 | G12: 64 | H12: =IF(AND(ISNUMBER(E12),E12>0),N(G12)/E12,"") -> 0.88888889 | I12: 100 | J12: 147 | K12: 85 | L12: =IF(AND(ISNUMBER(I12),I12>0),N(K12)/I12,"") -> 0.85 | M12: 48 | N12: 82 | O12: 26 | P12: =IF(AND(ISNUMBER(M12),M12>0),N(O12)/M12,"") -> 0.54166667 | Q12: 150 | R12: 74 | S12: =IF(AND(ISNUMBER(Q12),Q12>0),N(R12)/Q12,"") -> 0.49333333 | T12: 200 | U12: 105 | V12: =IF(AND(ISNUMBER(T12),T12>0),N(U12)/T12,"") -> 0.525 | Y12: 6 | Z12: 6 | AA12: 536000 | AB12: 760000 | AC12: Green | AD12: Release 2 moved into execution; defects triaged and closed quickly. Cumulative execution: 51 of 420 test cases (12%); 0 blocked; 0 open defects.
A13: 46262 | B13: 5 | C13: 0 | D13: =IF(N(B13)>0,1-N(C13)/(B13*Config!$B$15),"") -> 1 | E13: 72 | F13: 108 | G13: 67 | H13: =IF(AND(ISNUMBER(E13),E13>0),N(G13)/E13,"") -> 0.93055556 | I13: 100 | J13: 162 | K13: 89 | L13: =IF(AND(ISNUMBER(I13),I13>0),N(K13)/I13,"") -> 0.89 | M13: 48 | N13: 89 | O13: 28 | P13: =IF(AND(ISNUMBER(M13),M13>0),N(O13)/M13,"") -> 0.58333333 | Q13: 150 | R13: 80 | S13: =IF(AND(ISNUMBER(Q13),Q13>0),N(R13)/Q13,"") -> 0.53333333 | T13: 200 | U13: 112 | V13: =IF(AND(ISNUMBER(T13),T13>0),N(U13)/T13,"") -> 0.56 | Y13: 6 | Z13: 6 | AA13: 548000 | AB13: 760000 | AC13: Green | AD13: SIT on plan; test data automation passes the 50% mark. Cumulative execution: 75 of 420 test cases (18%); 0 blocked; 0 open defects.
A14: 46269 | B14: 5 | C14: 0 | D14: =IF(N(B14)>0,1-N(C14)/(B14*Config!$B$15),"") -> 1 | E14: 72 | F14: 115 | G14: 69 | H14: =IF(AND(ISNUMBER(E14),E14>0),N(G14)/E14,"") -> 0.95833333 | I14: 100 | J14: 173 | K14: 93 | L14: =IF(AND(ISNUMBER(I14),I14>0),N(K14)/I14,"") -> 0.93 | M14: 48 | N14: 96 | O14: 29 | P14: =IF(AND(ISNUMBER(M14),M14>0),N(O14)/M14,"") -> 0.60416667 | Q14: 150 | R14: 86 | S14: =IF(AND(ISNUMBER(Q14),Q14>0),N(R14)/Q14,"") -> 0.57333333 | T14: 200 | U14: 120 | V14: =IF(AND(ISNUMBER(T14),T14>0),N(U14)/T14,"") -> 0.6 | Y14: 6 | Z14: 6 | AA14: 560000 | AB14: 760000 | AC14: Green | AD14: Release 3 test design progressing; Digital Filing design started. Cumulative execution: 99 of 420 test cases (24%); 1 blocked; 1 open defect.
A15: 46276 | B15: 5 | C15: 1 | D15: =IF(N(B15)>0,1-N(C15)/(B15*Config!$B$15),"") -> 0.975 | E15: 72 | F15: 122 | G15: 71 | H15: =IF(AND(ISNUMBER(E15),E15>0),N(G15)/E15,"") -> 0.98611111 | I15: 100 | J15: 183 | K15: 95 | L15: =IF(AND(ISNUMBER(I15),I15>0),N(K15)/I15,"") -> 0.95 | M15: 48 | N15: 101 | O15: 29 | P15: =IF(AND(ISNUMBER(M15),M15>0),N(O15)/M15,"") -> 0.60416667 | Q15: 150 | R15: 91 | S15: =IF(AND(ISNUMBER(Q15),Q15>0),N(R15)/Q15,"") -> 0.60666667 | T15: 200 | U15: 128 | V15: =IF(AND(ISNUMBER(T15),T15>0),N(U15)/T15,"") -> 0.64 | Y15: 6 | Z15: 6 | AA15: 573000 | AB15: 760000 | AC15: Green | AD15: Execution tracking to plan; all defects closed within SLA. Cumulative execution: 132 of 420 test cases (31%); 0 blocked; 0 open defects.
A16: 46283 | B16: 5 | C16: 0 | D16: =IF(N(B16)>0,1-N(C16)/(B16*Config!$B$15),"") -> 1 | E16: 72 | F16: 125 | G16: 71 | H16: =IF(AND(ISNUMBER(E16),E16>0),N(G16)/E16,"") -> 0.98611111 | I16: 100 | J16: 188 | K16: 96 | L16: =IF(AND(ISNUMBER(I16),I16>0),N(K16)/I16,"") -> 0.96 | M16: 48 | N16: 104 | O16: 29 | P16: =IF(AND(ISNUMBER(M16),M16>0),N(O16)/M16,"") -> 0.60416667 | Q16: 150 | R16: 97 | S16: =IF(AND(ISNUMBER(Q16),Q16>0),N(R16)/Q16,"") -> 0.64666667 | T16: 200 | U16: 135 | V16: =IF(AND(ISNUMBER(T16),T16>0),N(U16)/T16,"") -> 0.675 | Y16: 6 | Z16: 6 | AA16: 585000 | AB16: 760000 | AC16: Green | AD16: No new defects; coverage of High and Medium risk requirements at or above target. Cumulative execution: 165 of 420 test cases (39%); 0 blocked; 0 open defects. | AE16: No new defects raised.
A17: 46290 | B17: 5 | C17: 1 | D17: =IF(N(B17)>0,1-N(C17)/(B17*Config!$B$15),"") -> 0.975 | E17: 72 | F17: 126 | G17: 72 | H17: =IF(AND(ISNUMBER(E17),E17>0),N(G17)/E17,"") -> 1 | I17: 100 | J17: 189 | K17: 97 | L17: =IF(AND(ISNUMBER(I17),I17>0),N(K17)/I17,"") -> 0.97 | M17: 48 | N17: 105 | O17: 30 | P17: =IF(AND(ISNUMBER(M17),M17>0),N(O17)/M17,"") -> 0.625 | Q17: 150 | R17: 102 | S17: =IF(AND(ISNUMBER(Q17),Q17>0),N(R17)/Q17,"") -> 0.68 | T17: 200 | U17: 142 | V17: =IF(AND(ISNUMBER(T17),T17>0),N(U17)/T17,"") -> 0.71 | Y17: 6 | Z17: 6 | AA17: 596000 | AB17: 760000 | AC17: Green | AD17: Release 2 execution passes the halfway mark; environment stable. Cumulative execution: 199 of 420 test cases (47%); 0 blocked; 0 open defects.
A18: 46297 | B18: 5 | C18: 0 | D18: =IF(N(B18)>0,1-N(C18)/(B18*Config!$B$15),"") -> 1 | E18: 72 | F18: 126 | G18: 72 | H18: =IF(AND(ISNUMBER(E18),E18>0),N(G18)/E18,"") -> 1 | I18: 100 | J18: 189 | K18: 97 | L18: =IF(AND(ISNUMBER(I18),I18>0),N(K18)/I18,"") -> 0.97 | M18: 48 | N18: 105 | O18: 30 | P18: =IF(AND(ISNUMBER(M18),M18>0),N(O18)/M18,"") -> 0.625 | Q18: 150 | R18: 108 | S18: =IF(AND(ISNUMBER(Q18),Q18>0),N(R18)/Q18,"") -> 0.72 | T18: 200 | U18: 150 | V18: =IF(AND(ISNUMBER(T18),T18>0),N(U18)/T18,"") -> 0.75 | Y18: 6 | Z18: 6 | AA18: 608000 | AB18: 760000 | AC18: Green | AD18: Portfolio remains Green: execution on plan, one low-priority defect in triage, spend and forecast aligned to budget. Cumulative execution: 232 of 420 test cases (55%); 3 blocked; 1 open defect.
D19: =IF(N(B19)>0,1-N(C19)/(B19*Config!$B$15),"") | H19: =IF(AND(ISNUMBER(E19),E19>0),N(G19)/E19,"") | L19: =IF(AND(ISNUMBER(I19),I19>0),N(K19)/I19,"") | P19: =IF(AND(ISNUMBER(M19),M19>0),N(O19)/M19,"") | S19: =IF(AND(ISNUMBER(Q19),Q19>0),N(R19)/Q19,"") | V19: =IF(AND(ISNUMBER(T19),T19>0),N(U19)/T19,"")
D20: =IF(N(B20)>0,1-N(C20)/(B20*Config!$B$15),"") | H20: =IF(AND(ISNUMBER(E20),E20>0),N(G20)/E20,"") | L20: =IF(AND(ISNUMBER(I20),I20>0),N(K20)/I20,"") | P20: =IF(AND(ISNUMBER(M20),M20>0),N(O20)/M20,"") | S20: =IF(AND(ISNUMBER(Q20),Q20>0),N(R20)/Q20,"") | V20: =IF(AND(ISNUMBER(T20),T20>0),N(U20)/T20,"")
D21: =IF(N(B21)>0,1-N(C21)/(B21*Config!$B$15),"") | H21: =IF(AND(ISNUMBER(E21),E21>0),N(G21)/E21,"") | L21: =IF(AND(ISNUMBER(I21),I21>0),N(K21)/I21,"") | P21: =IF(AND(ISNUMBER(M21),M21>0),N(O21)/M21,"") | S21: =IF(AND(ISNUMBER(Q21),Q21>0),N(R21)/Q21,"") | V21: =IF(AND(ISNUMBER(T21),T21>0),N(U21)/T21,"")
D22: =IF(N(B22)>0,1-N(C22)/(B22*Config!$B$15),"") | H22: =IF(AND(ISNUMBER(E22),E22>0),N(G22)/E22,"") | L22: =IF(AND(ISNUMBER(I22),I22>0),N(K22)/I22,"") | P22: =IF(AND(ISNUMBER(M22),M22>0),N(O22)/M22,"") | S22: =IF(AND(ISNUMBER(Q22),Q22>0),N(R22)/Q22,"") | V22: =IF(AND(ISNUMBER(T22),T22>0),N(U22)/T22,"")
D23: =IF(N(B23)>0,1-N(C23)/(B23*Config!$B$15),"") | H23: =IF(AND(ISNUMBER(E23),E23>0),N(G23)/E23,"") | L23: =IF(AND(ISNUMBER(I23),I23>0),N(K23)/I23,"") | P23: =IF(AND(ISNUMBER(M23),M23>0),N(O23)/M23,"") | S23: =IF(AND(ISNUMBER(Q23),Q23>0),N(R23)/Q23,"") | V23: =IF(AND(ISNUMBER(T23),T23>0),N(U23)/T23,"")
D24: =IF(N(B24)>0,1-N(C24)/(B24*Config!$B$15),"") | H24: =IF(AND(ISNUMBER(E24),E24>0),N(G24)/E24,"") | L24: =IF(AND(ISNUMBER(I24),I24>0),N(K24)/I24,"") | P24: =IF(AND(ISNUMBER(M24),M24>0),N(O24)/M24,"") | S24: =IF(AND(ISNUMBER(Q24),Q24>0),N(R24)/Q24,"") | V24: =IF(AND(ISNUMBER(T24),T24>0),N(U24)/T24,"")
D25: =IF(N(B25)>0,1-N(C25)/(B25*Config!$B$15),"") | H25: =IF(AND(ISNUMBER(E25),E25>0),N(G25)/E25,"") | L25: =IF(AND(ISNUMBER(I25),I25>0),N(K25)/I25,"") | P25: =IF(AND(ISNUMBER(M25),M25>0),N(O25)/M25,"") | S25: =IF(AND(ISNUMBER(Q25),Q25>0),N(R25)/Q25,"") | V25: =IF(AND(ISNUMBER(T25),T25>0),N(U25)/T25,"")
D26: =IF(N(B26)>0,1-N(C26)/(B26*Config!$B$15),"") | H26: =IF(AND(ISNUMBER(E26),E26>0),N(G26)/E26,"") | L26: =IF(AND(ISNUMBER(I26),I26>0),N(K26)/I26,"") | P26: =IF(AND(ISNUMBER(M26),M26>0),N(O26)/M26,"") | S26: =IF(AND(ISNUMBER(Q26),Q26>0),N(R26)/Q26,"") | V26: =IF(AND(ISNUMBER(T26),T26>0),N(U26)/T26,"")
D27: =IF(N(B27)>0,1-N(C27)/(B27*Config!$B$15),"") | H27: =IF(AND(ISNUMBER(E27),E27>0),N(G27)/E27,"") | L27: =IF(AND(ISNUMBER(I27),I27>0),N(K27)/I27,"") | P27: =IF(AND(ISNUMBER(M27),M27>0),N(O27)/M27,"") | S27: =IF(AND(ISNUMBER(Q27),Q27>0),N(R27)/Q27,"") | V27: =IF(AND(ISNUMBER(T27),T27>0),N(U27)/T27,"")
D28: =IF(N(B28)>0,1-N(C28)/(B28*Config!$B$15),"") | H28: =IF(AND(ISNUMBER(E28),E28>0),N(G28)/E28,"") | L28: =IF(AND(ISNUMBER(I28),I28>0),N(K28)/I28,"") | P28: =IF(AND(ISNUMBER(M28),M28>0),N(O28)/M28,"") | S28: =IF(AND(ISNUMBER(Q28),Q28>0),N(R28)/Q28,"") | V28: =IF(AND(ISNUMBER(T28),T28>0),N(U28)/T28,"")
D29: =IF(N(B29)>0,1-N(C29)/(B29*Config!$B$15),"") | H29: =IF(AND(ISNUMBER(E29),E29>0),N(G29)/E29,"") | L29: =IF(AND(ISNUMBER(I29),I29>0),N(K29)/I29,"") | P29: =IF(AND(ISNUMBER(M29),M29>0),N(O29)/M29,"") | S29: =IF(AND(ISNUMBER(Q29),Q29>0),N(R29)/Q29,"") | V29: =IF(AND(ISNUMBER(T29),T29>0),N(U29)/T29,"")
D30: =IF(N(B30)>0,1-N(C30)/(B30*Config!$B$15),"") | H30: =IF(AND(ISNUMBER(E30),E30>0),N(G30)/E30,"") | L30: =IF(AND(ISNUMBER(I30),I30>0),N(K30)/I30,"") | P30: =IF(AND(ISNUMBER(M30),M30>0),N(O30)/M30,"") | S30: =IF(AND(ISNUMBER(Q30),Q30>0),N(R30)/Q30,"") | V30: =IF(AND(ISNUMBER(T30),T30>0),N(U30)/T30,"")
... D305: =IF(N(B305)>0,1-N(C305)/(B305*Config!$B$15),"") | H305: =IF(AND(ISNUMBER(E305),E305>0),N(G305)/E305,"") | L305: =IF(AND(ISNUMBER(I305),I305>0),N(K305)/I305,"") | P305: =IF(AND(ISNUMBER(M305),M305>0),N(O305)/M305,"") | S305: =IF(AND(ISNUMBER(Q305),Q305>0),N(R305)/Q305,"") | V305: =IF(AND(ISNUMBER(T305),T305>0),N(U305)/T305,"")

Sheet Topic_Progress
A1: Topic_Progress [SAMPLE DATA – illustrative]
A2: One row per topic per week. All counts are CUMULATIVE to date at that Week Ending.
A3: HOW TO FILL: each Friday add one row for every active topic; pick Topic and Phase from the dropdowns. Executed and % columns calculate themselves.
A5: Week Ending | B5: Topic | C5: Phase | D5: TCs Planned | E5: TCs Designed | F5: Passed | G5: Failed | H5: Blocked | I5: Executed | J5: % Executed | K5: % Designed | L5: Comments | M5: Notes
A6: 46213 | B6: Self Assessment – Release 1 | C6: Test Prep | D6: 140 | E6: 14 | F6: 0 | G6: 0 | H6: 0 | I6: =IF(AND(A6="",F6="",G6=""),"",N(F6)+N(G6)) -> 0 | J6: =IF(AND(ISNUMBER(D6),D6>0,ISNUMBER(I6)),I6/D6,"") -> 0 | K6: =IF(AND(ISNUMBER(D6),D6>0),N(E6)/D6,"") -> 0.1 | L6: Test design 10% complete.
A7: 46220 | B7: Self Assessment – Release 1 | C7: Test Prep | D7: 140 | E7: 27 | F7: 0 | G7: 0 | H7: 0 | I7: =IF(AND(A7="",F7="",G7=""),"",N(F7)+N(G7)) -> 0 | J7: =IF(AND(ISNUMBER(D7),D7>0,ISNUMBER(I7)),I7/D7,"") -> 0 | K7: =IF(AND(ISNUMBER(D7),D7>0),N(E7)/D7,"") -> 0.19285714 | L7: Test design 19% complete.
A8: 46227 | B8: Self Assessment – Release 1 | C8: Test Prep | D8: 140 | E8: 58 | F8: 0 | G8: 0 | H8: 0 | I8: =IF(AND(A8="",F8="",G8=""),"",N(F8)+N(G8)) -> 0 | J8: =IF(AND(ISNUMBER(D8),D8>0,ISNUMBER(I8)),I8/D8,"") -> 0 | K8: =IF(AND(ISNUMBER(D8),D8>0),N(E8)/D8,"") -> 0.41428571 | L8: Test design 41% complete.
A9: 46234 | B9: Self Assessment – Release 1 | C9: Test Prep | D9: 140 | E9: 96 | F9: 0 | G9: 0 | H9: 0 | I9: =IF(AND(A9="",F9="",G9=""),"",N(F9)+N(G9)) -> 0 | J9: =IF(AND(ISNUMBER(D9),D9>0,ISNUMBER(I9)),I9/D9,"") -> 0 | K9: =IF(AND(ISNUMBER(D9),D9>0),N(E9)/D9,"") -> 0.68571429 | L9: Test design 69% complete.
A10: 46241 | B10: Self Assessment – Release 1 | C10: Smoke | D10: 140 | E10: 127 | F10: 12 | G10: 1 | H10: 0 | I10: =IF(AND(A10="",F10="",G10=""),"",N(F10)+N(G10)) -> 13 | J10: =IF(AND(ISNUMBER(D10),D10>0,ISNUMBER(I10)),I10/D10,"") -> 0.092857143 | K10: =IF(AND(ISNUMBER(D10),D10>0),N(E10)/D10,"") -> 0.90714286 | L10: 13 executed (12 passed, 1 failed); 0 blocked.
A11: 46248 | B11: Self Assessment – Release 1 | C11: SIT | D11: 140 | E11: 140 | F11: 24 | G11: 2 | H11: 0 | I11: =IF(AND(A11="",F11="",G11=""),"",N(F11)+N(G11)) -> 26 | J11: =IF(AND(ISNUMBER(D11),D11>0,ISNUMBER(I11)),I11/D11,"") -> 0.18571429 | K11: =IF(AND(ISNUMBER(D11),D11>0),N(E11)/D11,"") -> 1 | L11: 26 executed (24 passed, 2 failed); 0 blocked.
A12: 46255 | B12: Self Assessment – Release 1 | C12: SIT | D12: 140 | E12: 140 | F12: 37 | G12: 3 | H12: 0 | I12: =IF(AND(A12="",F12="",G12=""),"",N(F12)+N(G12)) -> 40 | J12: =IF(AND(ISNUMBER(D12),D12>0,ISNUMBER(I12)),I12/D12,"") -> 0.28571429 | K12: =IF(AND(ISNUMBER(D12),D12>0),N(E12)/D12,"") -> 1 | L12: 40 executed (37 passed, 3 failed); 0 blocked.
A13: 46262 | B13: Self Assessment – Release 1 | C13: SIT | D13: 140 | E13: 140 | F13: 49 | G13: 4 | H13: 0 | I13: =IF(AND(A13="",F13="",G13=""),"",N(F13)+N(G13)) -> 53 | J13: =IF(AND(ISNUMBER(D13),D13>0,ISNUMBER(I13)),I13/D13,"") -> 0.37857143 | K13: =IF(AND(ISNUMBER(D13),D13>0),N(E13)/D13,"") -> 1 | L13: 53 executed (49 passed, 4 failed); 0 blocked.
A14: 46269 | B14: Self Assessment – Release 1 | C14: SIT | D14: 140 | E14: 140 | F14: 61 | G14: 5 | H14: 0 | I14: =IF(AND(A14="",F14="",G14=""),"",N(F14)+N(G14)) -> 66 | J14: =IF(AND(ISNUMBER(D14),D14>0,ISNUMBER(I14)),I14/D14,"") -> 0.47142857 | K14: =IF(AND(ISNUMBER(D14),D14>0),N(E14)/D14,"") -> 1 | L14: 66 executed (61 passed, 5 failed); 0 blocked.
A15: 46276 | B15: Self Assessment – Release 1 | C15: SIT | D15: 140 | E15: 140 | F15: 73 | G15: 6 | H15: 0 | I15: =IF(AND(A15="",F15="",G15=""),"",N(F15)+N(G15)) -> 79 | J15: =IF(AND(ISNUMBER(D15),D15>0,ISNUMBER(I15)),I15/D15,"") -> 0.56428571 | K15: =IF(AND(ISNUMBER(D15),D15>0),N(E15)/D15,"") -> 1 | L15: 79 executed (73 passed, 6 failed); 0 blocked.
A16: 46283 | B16: Self Assessment – Release 1 | C16: SIT | D16: 140 | E16: 140 | F16: 86 | G16: 7 | H16: 0 | I16: =IF(AND(A16="",F16="",G16=""),"",N(F16)+N(G16)) -> 93 | J16: =IF(AND(ISNUMBER(D16),D16>0,ISNUMBER(I16)),I16/D16,"") -> 0.66428571 | K16: =IF(AND(ISNUMBER(D16),D16>0),N(E16)/D16,"") -> 1 | L16: 93 executed (86 passed, 7 failed); 0 blocked.
A17: 46290 | B17: Self Assessment – Release 1 | C17: SIT | D17: 140 | E17: 140 | F17: 99 | G17: 7 | H17: 0 | I17: =IF(AND(A17="",F17="",G17=""),"",N(F17)+N(G17)) -> 106 | J17: =IF(AND(ISNUMBER(D17),D17>0,ISNUMBER(I17)),I17/D17,"") -> 0.75714286 | K17: =IF(AND(ISNUMBER(D17),D17>0),N(E17)/D17,"") -> 1 | L17: 106 executed (99 passed, 7 failed); 0 blocked.
... A51: 46297 | B51: Self Assessment – Digital Filing | C51: SIT | D51: 70 | E51: 63 | F51: 4 | G51: 0 | H51: 0 | I51: =IF(AND(A51="",F51="",G51=""),"",N(F51)+N(G51)) -> 4 | J51: =IF(AND(ISNUMBER(D51),D51>0,ISNUMBER(I51)),I51/D51,"") -> 0.057142857 | K51: =IF(AND(ISNUMBER(D51),D51>0),N(E51)/D51,"") -> 0.9 | L51: 4 executed (4 passed, 0 failed); 0 blocked.
I52: =IF(AND(A52="",F52="",G52=""),"",N(F52)+N(G52)) | J52: =IF(AND(ISNUMBER(D52),D52>0,ISNUMBER(I52)),I52/D52,"") | K52: =IF(AND(ISNUMBER(D52),D52>0),N(E52)/D52,"")
I53: =IF(AND(A53="",F53="",G53=""),"",N(F53)+N(G53)) | J53: =IF(AND(ISNUMBER(D53),D53>0,ISNUMBER(I53)),I53/D53,"") | K53: =IF(AND(ISNUMBER(D53),D53>0),N(E53)/D53,"")
I54: =IF(AND(A54="",F54="",G54=""),"",N(F54)+N(G54)) | J54: =IF(AND(ISNUMBER(D54),D54>0,ISNUMBER(I54)),I54/D54,"") | K54: =IF(AND(ISNUMBER(D54),D54>0),N(E54)/D54,"")
I55: =IF(AND(A55="",F55="",G55=""),"",N(F55)+N(G55)) | J55: =IF(AND(ISNUMBER(D55),D55>0,ISNUMBER(I55)),I55/D55,"") | K55: =IF(AND(ISNUMBER(D55),D55>0),N(E55)/D55,"")
I56: =IF(AND(A56="",F56="",G56=""),"",N(F56)+N(G56)) | J56: =IF(AND(ISNUMBER(D56),D56>0,ISNUMBER(I56)),I56/D56,"") | K56: =IF(AND(ISNUMBER(D56),D56>0),N(E56)/D56,"")
I57: =IF(AND(A57="",F57="",G57=""),"",N(F57)+N(G57)) | J57: =IF(AND(ISNUMBER(D57),D57>0,ISNUMBER(I57)),I57/D57,"") | K57: =IF(AND(ISNUMBER(D57),D57>0),N(E57)/D57,"")
I58: =IF(AND(A58="",F58="",G58=""),"",N(F58)+N(G58)) | J58: =IF(AND(ISNUMBER(D58),D58>0,ISNUMBER(I58)),I58/D58,"") | K58: =IF(AND(ISNUMBER(D58),D58>0),N(E58)/D58,"")
I59: =IF(AND(A59="",F59="",G59=""),"",N(F59)+N(G59)) | J59: =IF(AND(ISNUMBER(D59),D59>0,ISNUMBER(I59)),I59/D59,"") | K59: =IF(AND(ISNUMBER(D59),D59>0),N(E59)/D59,"")
I60: =IF(AND(A60="",F60="",G60=""),"",N(F60)+N(G60)) | J60: =IF(AND(ISNUMBER(D60),D60>0,ISNUMBER(I60)),I60/D60,"") | K60: =IF(AND(ISNUMBER(D60),D60>0),N(E60)/D60,"")
I61: =IF(AND(A61="",F61="",G61=""),"",N(F61)+N(G61)) | J61: =IF(AND(ISNUMBER(D61),D61>0,ISNUMBER(I61)),I61/D61,"") | K61: =IF(AND(ISNUMBER(D61),D61>0),N(E61)/D61,"")
I62: =IF(AND(A62="",F62="",G62=""),"",N(F62)+N(G62)) | J62: =IF(AND(ISNUMBER(D62),D62>0,ISNUMBER(I62)),I62/D62,"") | K62: =IF(AND(ISNUMBER(D62),D62>0),N(E62)/D62,"")
I63: =IF(AND(A63="",F63="",G63=""),"",N(F63)+N(G63)) | J63: =IF(AND(ISNUMBER(D63),D63>0,ISNUMBER(I63)),I63/D63,"") | K63: =IF(AND(ISNUMBER(D63),D63>0),N(E63)/D63,"")
... I305: =IF(AND(A305="",F305="",G305=""),"",N(F305)+N(G305)) | J305: =IF(AND(ISNUMBER(D305),D305>0,ISNUMBER(I305)),I305/D305,"") | K305: =IF(AND(ISNUMBER(D305),D305>0),N(E305)/D305,"")

Sheet Defect_Log
A1: Defect_Log [SAMPLE DATA – illustrative]
A2: One row per defect. Aging is in working days (inclusive) from Raised Date to Resolved Date (or today while open).
A3: HOW TO FILL: add each defect when raised; set Resolved Date when fix + confirmation test is complete (or on rejection). Aging and bucket calculate themselves.
A5: Defect ID | B5: Summary | C5: Topic | D5: Test Type | E5: Priority | F5: Severity | G5: Raised Date | H5: Resolved Date | I5: Status | J5: Found In | K5: Owner / DG | L5: TCs Blocked | M5: Triage Comments | N5: Aging (Working Days) | O5: Aging Bucket | P5: Notes
A6: SA-101 | B6: Tax calculation – message queued but not delivered | C6: Self Assessment – Release 1 | D6: Smoke | E6: P2 Medium | F6: 3 - High | G6: 46239 | H6: 46240 | I6: Closed | J6: Testing | K6: Data Team | L6: 0 | M6: Fix delivered and confirmed by retest. | N6: =IF(OR(A6="",G6=""),"",MAX(1,NETWORKDAYS(G6,IF(H6="",TODAY(),H6),Bank_Holidays!$A$6:$A$60))) -> 2 | O6: =IF(N6="","",IF(N6<=2,"0-2 Days",IF(N6<=5,"3-5 Days",IF(N6<=10,"6-10 Days",">10 Days")))) -> 0-2 Days
A7: SA-102 | B7: Return submission – field truncated in output | C7: Self Assessment – Release 1 | D7: Smoke | E7: P3 Low | F7: 5 - Low | G7: 46247 | H7: 46247 | I7: Closed | J7: Testing | K7: Environments | L7: 0 | M7: Fix delivered and confirmed by retest. | N7: =IF(OR(A7="",G7=""),"",MAX(1,NETWORKDAYS(G7,IF(H7="",TODAY(),H7),Bank_Holidays!$A$6:$A$60))) -> 1 | O7: =IF(N7="","",IF(N7<=2,"0-2 Days",IF(N7<=5,"3-5 Days",IF(N7<=10,"6-10 Days",">10 Days")))) -> 0-2 Days
A8: SA-103 | B8: Return submission – error returned for valid input | C8: Self Assessment – Release 1 | D8: SIT | E8: P2 Medium | F8: 4 - Standard | G8: 46253 | H8: 46255 | I8: Closed | J8: Testing | K8: Supplier A | L8: 0 | M8: Fix delivered and confirmed by retest. | N8: =IF(OR(A8="",G8=""),"",MAX(1,NETWORKDAYS(G8,IF(H8="",TODAY(),H8),Bank_Holidays!$A$6:$A$60))) -> 3 | O8: =IF(N8="","",IF(N8<=2,"0-2 Days",IF(N8<=5,"3-5 Days",IF(N8<=10,"6-10 Days",">10 Days")))) -> 3-5 Days
A9: SA-104 | B9: Online filing – status not updated after processing | C9: Self Assessment – Release 1 | D9: SIT | E9: P3 Low | F9: 6 - Trivial | G9: 46259 | H9: 46262 | I9: Resolved | J9: Testing | K9: Dev Team 1 | L9: 0 | M9: Fix delivered and confirmed by retest. | N9: =IF(OR(A9="",G9=""),"",MAX(1,NETWORKDAYS(G9,IF(H9="",TODAY(),H9),Bank_Holidays!$A$6:$A$60))) -> 4 | O9: =IF(N9="","",IF(N9<=2,"0-2 Days",IF(N9<=5,"3-5 Days",IF(N9<=10,"6-10 Days",">10 Days")))) -> 3-5 Days
A10: SA-105 | B10: Penalty notice – notification not issued | C10: Self Assessment – Release 2 | D10: SIT | E10: P1 High | F10: 3 - High | G10: 46261 | H10: 46262 | I10: Closed | J10: Testing | K10: Dev Team 2 | L10: 2 | M10: Fix delivered and confirmed by retest. | N10: =IF(OR(A10="",G10=""),"",MAX(1,NETWORKDAYS(G10,IF(H10="",TODAY(),H10),Bank_Holidays!$A$6:$A$60))) -> 2 | O10: =IF(N10="","",IF(N10<=2,"0-2 Days",IF(N10<=5,"3-5 Days",IF(N10<=10,"6-10 Days",">10 Days")))) -> 0-2 Days
A11: SA-106 | B11: Account summary – validation message missing | C11: Self Assessment – Release 2 | D11: SIT | E11: P2 Medium | F11: 3 - High | G11: 46267 | H11: 46275 | I11: Closed | J11: Testing | K11: Integration Team | L11: 1 | M11: Fix delivered and confirmed by retest. | N11: =IF(OR(A11="",G11=""),"",MAX(1,NETWORKDAYS(G11,IF(H11="",TODAY(),H11),Bank_Holidays!$A$6:$A$60))) -> 7 | O11: =IF(N11="","",IF(N11<=2,"0-2 Days",IF(N11<=5,"3-5 Days",IF(N11<=10,"6-10 Days",">10 Days")))) -> 6-10 Days
A12: SA-107 | B12: Penalty notice – error returned for valid input | C12: Self Assessment – Release 1 | D12: SIT | E12: P2 Medium | F12: 4 - Standard | G12: 46275 | H12: 46276 | I12: Closed | J12: Testing | K12: Data Team | L12: 2 | M12: Fix delivered and confirmed by retest. | N12: =IF(OR(A12="",G12=""),"",MAX(1,NETWORKDAYS(G12,IF(H12="",TODAY(),H12),Bank_Holidays!$A$6:$A$60))) -> 2 | O12: =IF(N12="","",IF(N12<=2,"0-2 Days",IF(N12<=5,"3-5 Days",IF(N12<=10,"6-10 Days",">10 Days")))) -> 0-2 Days
A13: SA-108 | B13: Online filing – message queued but not delivered | C13: Self Assessment – Digital Filing | D13: SIT | E13: P3 Low | F13: 6 - Trivial | G13: 46287 | H13: 46289 | I13: Resolved | J13: Testing | K13: Environments | L13: 0 | M13: Fix delivered and confirmed by retest. | N13: =IF(OR(A13="",G13=""),"",MAX(1,NETWORKDAYS(G13,IF(H13="",TODAY(),H13),Bank_Holidays!$A$6:$A$60))) -> 3 | O13: =IF(N13="","",IF(N13<=2,"0-2 Days",IF(N13<=5,"3-5 Days",IF(N13<=10,"6-10 Days",">10 Days")))) -> 3-5 Days
A14: SA-109 | B14: Account summary – stale data returned after update | C14: Self Assessment – Release 3 | D14: SIT | E14: P3 Low | F14: 5 - Low | G14: 46296 | I14: In Progress | J14: Testing | K14: Supplier A | L14: 3 | M14: With Supplier A for fix; retest pending. | N14: =IF(OR(A14="",G14=""),"",MAX(1,NETWORKDAYS(G14,IF(H14="",TODAY(),H14),Bank_Holidays!$A$6:$A$60))) -> 2 | O14: =IF(N14="","",IF(N14<=2,"0-2 Days",IF(N14<=5,"3-5 Days",IF(N14<=10,"6-10 Days",">10 Days")))) -> 0-2 Days
N15: =IF(OR(A15="",G15=""),"",MAX(1,NETWORKDAYS(G15,IF(H15="",TODAY(),H15),Bank_Holidays!$A$6:$A$60))) | O15: =IF(N15="","",IF(N15<=2,"0-2 Days",IF(N15<=5,"3-5 Days",IF(N15<=10,"6-10 Days",">10 Days"))))
N16: =IF(OR(A16="",G16=""),"",MAX(1,NETWORKDAYS(G16,IF(H16="",TODAY(),H16),Bank_Holidays!$A$6:$A$60))) | O16: =IF(N16="","",IF(N16<=2,"0-2 Days",IF(N16<=5,"3-5 Days",IF(N16<=10,"6-10 Days",">10 Days"))))
N17: =IF(OR(A17="",G17=""),"",MAX(1,NETWORKDAYS(G17,IF(H17="",TODAY(),H17),Bank_Holidays!$A$6:$A$60))) | O17: =IF(N17="","",IF(N17<=2,"0-2 Days",IF(N17<=5,"3-5 Days",IF(N17<=10,"6-10 Days",">10 Days"))))
N18: =IF(OR(A18="",G18=""),"",MAX(1,NETWORKDAYS(G18,IF(H18="",TODAY(),H18),Bank_Holidays!$A$6:$A$60))) | O18: =IF(N18="","",IF(N18<=2,"0-2 Days",IF(N18<=5,"3-5 Days",IF(N18<=10,"6-10 Days",">10 Days"))))
N19: =IF(OR(A19="",G19=""),"",MAX(1,NETWORKDAYS(G19,IF(H19="",TODAY(),H19),Bank_Holidays!$A$6:$A$60))) | O19: =IF(N19="","",IF(N19<=2,"0-2 Days",IF(N19<=5,"3-5 Days",IF(N19<=10,"6-10 Days",">10 Days"))))
N20: =IF(OR(A20="",G20=""),"",MAX(1,NETWORKDAYS(G20,IF(H20="",TODAY(),H20),Bank_Holidays!$A$6:$A$60))) | O20: =IF(N20="","",IF(N20<=2,"0-2 Days",IF(N20<=5,"3-5 Days",IF(N20<=10,"6-10 Days",">10 Days"))))
N21: =IF(OR(A21="",G21=""),"",MAX(1,NETWORKDAYS(G21,IF(H21="",TODAY(),H21),Bank_Holidays!$A$6:$A$60))) | O21: =IF(N21="","",IF(N21<=2,"0-2 Days",IF(N21<=5,"3-5 Days",IF(N21<=10,"6-10 Days",">10 Days"))))
N22: =IF(OR(A22="",G22=""),"",MAX(1,NETWORKDAYS(G22,IF(H22="",TODAY(),H22),Bank_Holidays!$A$6:$A$60))) | O22: =IF(N22="","",IF(N22<=2,"0-2 Days",IF(N22<=5,"3-5 Days",IF(N22<=10,"6-10 Days",">10 Days"))))
N23: =IF(OR(A23="",G23=""),"",MAX(1,NETWORKDAYS(G23,IF(H23="",TODAY(),H23),Bank_Holidays!$A$6:$A$60))) | O23: =IF(N23="","",IF(N23<=2,"0-2 Days",IF(N23<=5,"3-5 Days",IF(N23<=10,"6-10 Days",">10 Days"))))
N24: =IF(OR(A24="",G24=""),"",MAX(1,NETWORKDAYS(G24,IF(H24="",TODAY(),H24),Bank_Holidays!$A$6:$A$60))) | O24: =IF(N24="","",IF(N24<=2,"0-2 Days",IF(N24<=5,"3-5 Days",IF(N24<=10,"6-10 Days",">10 Days"))))
N25: =IF(OR(A25="",G25=""),"",MAX(1,NETWORKDAYS(G25,IF(H25="",TODAY(),H25),Bank_Holidays!$A$6:$A$60))) | O25: =IF(N25="","",IF(N25<=2,"0-2 Days",IF(N25<=5,"3-5 Days",IF(N25<=10,"6-10 Days",">10 Days"))))
N26: =IF(OR(A26="",G26=""),"",MAX(1,NETWORKDAYS(G26,IF(H26="",TODAY(),H26),Bank_Holidays!$A$6:$A$60))) | O26: =IF(N26="","",IF(N26<=2,"0-2 Days",IF(N26<=5,"3-5 Days",IF(N26<=10,"6-10 Days",">10 Days"))))
... N305: =IF(OR(A305="",G305=""),"",MAX(1,NETWORKDAYS(G305,IF(H305="",TODAY(),H305),Bank_Holidays!$A$6:$A$60))) | O305: =IF(N305="","",IF(N305<=2,"0-2 Days",IF(N305<=5,"3-5 Days",IF(N305<=10,"6-10 Days",">10 Days"))))

Sheet TSR_Log
A1: TSR_Log [SAMPLE DATA – illustrative]
A2: One row per Technical Service Request (TSR) received for impact assessment. Work Days exclude Hold Days.
A3: HOW TO FILL: add the TSR when received; fill Returned Date when sent back to the Front Desk and Hold Days for time pending clarification.
A5: TSR Ref | B5: Description | C5: Topic | D5: Received Date | E5: Returned Date | F5: Hold Days (pending clarification) | G5: Status | H5: Value (£) | I5: Work Days | J5: Over SLA? | K5: Notes
A6: TSR_PR021877-REQ031204 | B6: Raised for the portfolio's QA activities and resource estimation (the portfolio's own TSR). | C6: Programme (cross-cutting) | D6: 46076 | E6: 46084 | F6: 1 | G6: Returned | H6: 760000 | I6: =IF(OR(A6="",D6=""),"",MAX(0,NETWORKDAYS(D6,IF(E6="",TODAY(),E6),Bank_Holidays!$A$6:$A$60)-N(F6))) -> 6 | J6: =IF(I6="","",IF(I6>Config!$B$16,"Yes","No")) -> No
A7: TSR_PR021877-REQ031577 | B7: Test impact assessment for a related change request from another team. | C7: Programme (cross-cutting) | D7: 46160 | E7: 46164 | F7: 0 | G7: Returned | I7: =IF(OR(A7="",D7=""),"",MAX(0,NETWORKDAYS(D7,IF(E7="",TODAY(),E7),Bank_Holidays!$A$6:$A$60)-N(F7))) -> 5 | J7: =IF(I7="","",IF(I7>Config!$B$16,"Yes","No")) -> No
A8: PR022014-REQ031960 V2 | B8: Follow-on test estimate; returned after a scope clarification. | C8: Programme (cross-cutting) | D8: 46223 | E8: 46233 | F8: 2 | G8: Returned | I8: =IF(OR(A8="",D8=""),"",MAX(0,NETWORKDAYS(D8,IF(E8="",TODAY(),E8),Bank_Holidays!$A$6:$A$60)-N(F8))) -> 7 | J8: =IF(I8="","",IF(I8>Config!$B$16,"Yes","No")) -> No
A9: TSR_PR022014-REQ032301 | B9: Test impact assessment for a configuration change. | C9: Programme (cross-cutting) | D9: 46266 | E9: 46269 | F9: 0 | G9: Returned | I9: =IF(OR(A9="",D9=""),"",MAX(0,NETWORKDAYS(D9,IF(E9="",TODAY(),E9),Bank_Holidays!$A$6:$A$60)-N(F9))) -> 4 | J9: =IF(I9="","",IF(I9>Config!$B$16,"Yes","No")) -> No
A10: PR022310-REQ032588 | B10: Test impact assessment for a further change; assessment in progress. | C10: Programme (cross-cutting) | D10: 46293 | F10: 0 | G10: Open | I10: =IF(OR(A10="",D10=""),"",MAX(0,NETWORKDAYS(D10,IF(E10="",TODAY(),E10),Bank_Holidays!$A$6:$A$60)-N(F10))) -> 5 | J10: =IF(I10="","",IF(I10>Config!$B$16,"Yes","No")) -> No
I11: =IF(OR(A11="",D11=""),"",MAX(0,NETWORKDAYS(D11,IF(E11="",TODAY(),E11),Bank_Holidays!$A$6:$A$60)-N(F11))) | J11: =IF(I11="","",IF(I11>Config!$B$16,"Yes","No"))
I12: =IF(OR(A12="",D12=""),"",MAX(0,NETWORKDAYS(D12,IF(E12="",TODAY(),E12),Bank_Holidays!$A$6:$A$60)-N(F12))) | J12: =IF(I12="","",IF(I12>Config!$B$16,"Yes","No"))
I13: =IF(OR(A13="",D13=""),"",MAX(0,NETWORKDAYS(D13,IF(E13="",TODAY(),E13),Bank_Holidays!$A$6:$A$60)-N(F13))) | J13: =IF(I13="","",IF(I13>Config!$B$16,"Yes","No"))
I14: =IF(OR(A14="",D14=""),"",MAX(0,NETWORKDAYS(D14,IF(E14="",TODAY(),E14),Bank_Holidays!$A$6:$A$60)-N(F14))) | J14: =IF(I14="","",IF(I14>Config!$B$16,"Yes","No"))
I15: =IF(OR(A15="",D15=""),"",MAX(0,NETWORKDAYS(D15,IF(E15="",TODAY(),E15),Bank_Holidays!$A$6:$A$60)-N(F15))) | J15: =IF(I15="","",IF(I15>Config!$B$16,"Yes","No"))
I16: =IF(OR(A16="",D16=""),"",MAX(0,NETWORKDAYS(D16,IF(E16="",TODAY(),E16),Bank_Holidays!$A$6:$A$60)-N(F16))) | J16: =IF(I16="","",IF(I16>Config!$B$16,"Yes","No"))
I17: =IF(OR(A17="",D17=""),"",MAX(0,NETWORKDAYS(D17,IF(E17="",TODAY(),E17),Bank_Holidays!$A$6:$A$60)-N(F17))) | J17: =IF(I17="","",IF(I17>Config!$B$16,"Yes","No"))
I18: =IF(OR(A18="",D18=""),"",MAX(0,NETWORKDAYS(D18,IF(E18="",TODAY(),E18),Bank_Holidays!$A$6:$A$60)-N(F18))) | J18: =IF(I18="","",IF(I18>Config!$B$16,"Yes","No"))
I19: =IF(OR(A19="",D19=""),"",MAX(0,NETWORKDAYS(D19,IF(E19="",TODAY(),E19),Bank_Holidays!$A$6:$A$60)-N(F19))) | J19: =IF(I19="","",IF(I19>Config!$B$16,"Yes","No"))
I20: =IF(OR(A20="",D20=""),"",MAX(0,NETWORKDAYS(D20,IF(E20="",TODAY(),E20),Bank_Holidays!$A$6:$A$60)-N(F20))) | J20: =IF(I20="","",IF(I20>Config!$B$16,"Yes","No"))
I21: =IF(OR(A21="",D21=""),"",MAX(0,NETWORKDAYS(D21,IF(E21="",TODAY(),E21),Bank_Holidays!$A$6:$A$60)-N(F21))) | J21: =IF(I21="","",IF(I21>Config!$B$16,"Yes","No"))
I22: =IF(OR(A22="",D22=""),"",MAX(0,NETWORKDAYS(D22,IF(E22="",TODAY(),E22),Bank_Holidays!$A$6:$A$60)-N(F22))) | J22: =IF(I22="","",IF(I22>Config!$B$16,"Yes","No"))
... I305: =IF(OR(A305="",D305=""),"",MAX(0,NETWORKDAYS(D305,IF(E305="",TODAY(),E305),Bank_Holidays!$A$6:$A$60)-N(F305))) | J305: =IF(I305="","",IF(I305>Config!$B$16,"Yes","No"))

Sheet Milestones
A1: Milestones [SAMPLE DATA – illustrative]
A2: One row per test milestone with due, forecast and completed dates. Delay, status and RAG calculate against today's date.
A3: HOW TO FILL: add each milestone once; set Forecast Date if it slips and Completed Date when done. Critical? = Yes for key milestones.
A5: Milestone | B5: Topic | C5: Due Date | D5: Forecast Date | E5: Completed Date | F5: Owner | G5: Critical? | H5: Delay (Days) | I5: Status | J5: RAG | K5: Notes
A6: Test Approach | B6: Programme (cross-cutting) | C6: 46108 | E6: 46107 | F6: Programme Test Manager | G6: Yes | H6: =IF(OR(A6="",C6=""),"",IF(E6<>"",MAX(0,E6-C6),MAX(0,TODAY()-C6))) -> 0 | I6: =IF(OR(A6="",C6=""),"",IF(E6<>"",IF(E6<=C6,"Completed","Completed Late"),IF(TODAY()>C6,"Overdue","On Schedule"))) -> Completed | J6: =IF(OR(A6="",C6=""),"",IF(E6<>"",IF(E6<=C6,"Green","Red"),IF(TODAY()>C6,"Red",IF(C6-TODAY()<=Config!$B$30,"Amber","Green")))) -> Green
A7: Smoke Testing | B7: Self Assessment – Release 1 | C7: 46157 | E7: 46156 | F7: Test Manager | G7: Yes | H7: =IF(OR(A7="",C7=""),"",IF(E7<>"",MAX(0,E7-C7),MAX(0,TODAY()-C7))) -> 0 | I7: =IF(OR(A7="",C7=""),"",IF(E7<>"",IF(E7<=C7,"Completed","Completed Late"),IF(TODAY()>C7,"Overdue","On Schedule"))) -> Completed | J7: =IF(OR(A7="",C7=""),"",IF(E7<>"",IF(E7<=C7,"Green","Red"),IF(TODAY()>C7,"Red",IF(C7-TODAY()<=Config!$B$30,"Amber","Green")))) -> Green
A8: SIT Test Script Creation | B8: Self Assessment – Release 1 | C8: 46185 | E8: 46184 | F8: Test Lead | G8: Yes | H8: =IF(OR(A8="",C8=""),"",IF(E8<>"",MAX(0,E8-C8),MAX(0,TODAY()-C8))) -> 0 | I8: =IF(OR(A8="",C8=""),"",IF(E8<>"",IF(E8<=C8,"Completed","Completed Late"),IF(TODAY()>C8,"Overdue","On Schedule"))) -> Completed | J8: =IF(OR(A8="",C8=""),"",IF(E8<>"",IF(E8<=C8,"Green","Red"),IF(TODAY()>C8,"Red",IF(C8-TODAY()<=Config!$B$30,"Amber","Green")))) -> Green
A9: E2E Test Script Creation | B9: Self Assessment – Release 1 | C9: 46213 | E9: 46212 | F9: Test Lead | G9: Yes | H9: =IF(OR(A9="",C9=""),"",IF(E9<>"",MAX(0,E9-C9),MAX(0,TODAY()-C9))) -> 0 | I9: =IF(OR(A9="",C9=""),"",IF(E9<>"",IF(E9<=C9,"Completed","Completed Late"),IF(TODAY()>C9,"Overdue","On Schedule"))) -> Completed | J9: =IF(OR(A9="",C9=""),"",IF(E9<>"",IF(E9<=C9,"Green","Red"),IF(TODAY()>C9,"Red",IF(C9-TODAY()<=Config!$B$30,"Amber","Green")))) -> Green
A10: SIT Test Script Execution – Phase 1 | B10: Self Assessment – Release 1 | C10: 46283 | E10: 46282 | F10: Test Manager | G10: Yes | H10: =IF(OR(A10="",C10=""),"",IF(E10<>"",MAX(0,E10-C10),MAX(0,TODAY()-C10))) -> 0 | I10: =IF(OR(A10="",C10=""),"",IF(E10<>"",IF(E10<=C10,"Completed","Completed Late"),IF(TODAY()>C10,"Overdue","On Schedule"))) -> Completed | J10: =IF(OR(A10="",C10=""),"",IF(E10<>"",IF(E10<=C10,"Green","Red"),IF(TODAY()>C10,"Red",IF(C10-TODAY()<=Config!$B$30,"Amber","Green")))) -> Green
A11: SIT Test Script Execution – Phase 2 | B11: Self Assessment – Release 1 | C11: 46332 | F11: Test Manager | G11: No | H11: =IF(OR(A11="",C11=""),"",IF(E11<>"",MAX(0,E11-C11),MAX(0,TODAY()-C11))) -> 0 | I11: =IF(OR(A11="",C11=""),"",IF(E11<>"",IF(E11<=C11,"Completed","Completed Late"),IF(TODAY()>C11,"Overdue","On Schedule"))) -> On Schedule | J11: =IF(OR(A11="",C11=""),"",IF(E11<>"",IF(E11<=C11,"Green","Red"),IF(TODAY()>C11,"Red",IF(C11-TODAY()<=Config!$B$30,"Amber","Green")))) -> Green
A12: NFR Test Scripts Ready | B12: Self Assessment – Release 1 | C12: 46318 | F12: Test Lead | G12: No | H12: =IF(OR(A12="",C12=""),"",IF(E12<>"",MAX(0,E12-C12),MAX(0,TODAY()-C12))) -> 0 | I12: =IF(OR(A12="",C12=""),"",IF(E12<>"",IF(E12<=C12,"Completed","Completed Late"),IF(TODAY()>C12,"Overdue","On Schedule"))) -> On Schedule | J12: =IF(OR(A12="",C12=""),"",IF(E12<>"",IF(E12<=C12,"Green","Red"),IF(TODAY()>C12,"Red",IF(C12-TODAY()<=Config!$B$30,"Amber","Green")))) -> Green
A13: Automation of Smoke / Regression Testing | B13: Programme (cross-cutting) | C13: 46346 | F13: Automation Engineer 1 | G13: No | H13: =IF(OR(A13="",C13=""),"",IF(E13<>"",MAX(0,E13-C13),MAX(0,TODAY()-C13))) -> 0 | I13: =IF(OR(A13="",C13=""),"",IF(E13<>"",IF(E13<=C13,"Completed","Completed Late"),IF(TODAY()>C13,"Overdue","On Schedule"))) -> On Schedule | J13: =IF(OR(A13="",C13=""),"",IF(E13<>"",IF(E13<=C13,"Green","Red"),IF(TODAY()>C13,"Red",IF(C13-TODAY()<=Config!$B$30,"Amber","Green")))) -> Green
A14: E2E Test Script Execution | B14: Self Assessment – Release 1 | C14: 46360 | F14: Test Manager | G14: No | H14: =IF(OR(A14="",C14=""),"",IF(E14<>"",MAX(0,E14-C14),MAX(0,TODAY()-C14))) -> 0 | I14: =IF(OR(A14="",C14=""),"",IF(E14<>"",IF(E14<=C14,"Completed","Completed Late"),IF(TODAY()>C14,"Overdue","On Schedule"))) -> On Schedule | J14: =IF(OR(A14="",C14=""),"",IF(E14<>"",IF(E14<=C14,"Green","Red"),IF(TODAY()>C14,"Red",IF(C14-TODAY()<=Config!$B$30,"Amber","Green")))) -> Green
A15: Defect Retest Cycle 1 Complete | B15: Self Assessment – Release 1 | C15: 46353 | F15: Test Manager | G15: No | H15: =IF(OR(A15="",C15=""),"",IF(E15<>"",MAX(0,E15-C15),MAX(0,TODAY()-C15))) -> 0 | I15: =IF(OR(A15="",C15=""),"",IF(E15<>"",IF(E15<=C15,"Completed","Completed Late"),IF(TODAY()>C15,"Overdue","On Schedule"))) -> On Schedule | J15: =IF(OR(A15="",C15=""),"",IF(E15<>"",IF(E15<=C15,"Green","Red"),IF(TODAY()>C15,"Red",IF(C15-TODAY()<=Config!$B$30,"Amber","Green")))) -> Green
A16: Test Completion Report | B16: Programme (cross-cutting) | C16: 46374 | F16: Programme Test Manager | G16: No | H16: =IF(OR(A16="",C16=""),"",IF(E16<>"",MAX(0,E16-C16),MAX(0,TODAY()-C16))) -> 0 | I16: =IF(OR(A16="",C16=""),"",IF(E16<>"",IF(E16<=C16,"Completed","Completed Late"),IF(TODAY()>C16,"Overdue","On Schedule"))) -> On Schedule | J16: =IF(OR(A16="",C16=""),"",IF(E16<>"",IF(E16<=C16,"Green","Red"),IF(TODAY()>C16,"Red",IF(C16-TODAY()<=Config!$B$30,"Amber","Green")))) -> Green
H17: =IF(OR(A17="",C17=""),"",IF(E17<>"",MAX(0,E17-C17),MAX(0,TODAY()-C17))) | I17: =IF(OR(A17="",C17=""),"",IF(E17<>"",IF(E17<=C17,"Completed","Completed Late"),IF(TODAY()>C17,"Overdue","On Schedule"))) | J17: =IF(OR(A17="",C17=""),"",IF(E17<>"",IF(E17<=C17,"Green","Red"),IF(TODAY()>C17,"Red",IF(C17-TODAY()<=Config!$B$30,"Amber","Green"))))
H18: =IF(OR(A18="",C18=""),"",IF(E18<>"",MAX(0,E18-C18),MAX(0,TODAY()-C18))) | I18: =IF(OR(A18="",C18=""),"",IF(E18<>"",IF(E18<=C18,"Completed","Completed Late"),IF(TODAY()>C18,"Overdue","On Schedule"))) | J18: =IF(OR(A18="",C18=""),"",IF(E18<>"",IF(E18<=C18,"Green","Red"),IF(TODAY()>C18,"Red",IF(C18-TODAY()<=Config!$B$30,"Amber","Green"))))
H19: =IF(OR(A19="",C19=""),"",IF(E19<>"",MAX(0,E19-C19),MAX(0,TODAY()-C19))) | I19: =IF(OR(A19="",C19=""),"",IF(E19<>"",IF(E19<=C19,"Completed","Completed Late"),IF(TODAY()>C19,"Overdue","On Schedule"))) | J19: =IF(OR(A19="",C19=""),"",IF(E19<>"",IF(E19<=C19,"Green","Red"),IF(TODAY()>C19,"Red",IF(C19-TODAY()<=Config!$B$30,"Amber","Green"))))
H20: =IF(OR(A20="",C20=""),"",IF(E20<>"",MAX(0,E20-C20),MAX(0,TODAY()-C20))) | I20: =IF(OR(A20="",C20=""),"",IF(E20<>"",IF(E20<=C20,"Completed","Completed Late"),IF(TODAY()>C20,"Overdue","On Schedule"))) | J20: =IF(OR(A20="",C20=""),"",IF(E20<>"",IF(E20<=C20,"Green","Red"),IF(TODAY()>C20,"Red",IF(C20-TODAY()<=Config!$B$30,"Amber","Green"))))
H21: =IF(OR(A21="",C21=""),"",IF(E21<>"",MAX(0,E21-C21),MAX(0,TODAY()-C21))) | I21: =IF(OR(A21="",C21=""),"",IF(E21<>"",IF(E21<=C21,"Completed","Completed Late"),IF(TODAY()>C21,"Overdue","On Schedule"))) | J21: =IF(OR(A21="",C21=""),"",IF(E21<>"",IF(E21<=C21,"Green","Red"),IF(TODAY()>C21,"Red",IF(C21-TODAY()<=Config!$B$30,"Amber","Green"))))
H22: =IF(OR(A22="",C22=""),"",IF(E22<>"",MAX(0,E22-C22),MAX(0,TODAY()-C22))) | I22: =IF(OR(A22="",C22=""),"",IF(E22<>"",IF(E22<=C22,"Completed","Completed Late"),IF(TODAY()>C22,"Overdue","On Schedule"))) | J22: =IF(OR(A22="",C22=""),"",IF(E22<>"",IF(E22<=C22,"Green","Red"),IF(TODAY()>C22,"Red",IF(C22-TODAY()<=Config!$B$30,"Amber","Green"))))
H23: =IF(OR(A23="",C23=""),"",IF(E23<>"",MAX(0,E23-C23),MAX(0,TODAY()-C23))) | I23: =IF(OR(A23="",C23=""),"",IF(E23<>"",IF(E23<=C23,"Completed","Completed Late"),IF(TODAY()>C23,"Overdue","On Schedule"))) | J23: =IF(OR(A23="",C23=""),"",IF(E23<>"",IF(E23<=C23,"Green","Red"),IF(TODAY()>C23,"Red",IF(C23-TODAY()<=Config!$B$30,"Amber","Green"))))
H24: =IF(OR(A24="",C24=""),"",IF(E24<>"",MAX(0,E24-C24),MAX(0,TODAY()-C24))) | I24: =IF(OR(A24="",C24=""),"",IF(E24<>"",IF(E24<=C24,"Completed","Completed Late"),IF(TODAY()>C24,"Overdue","On Schedule"))) | J24: =IF(OR(A24="",C24=""),"",IF(E24<>"",IF(E24<=C24,"Green","Red"),IF(TODAY()>C24,"Red",IF(C24-TODAY()<=Config!$B$30,"Amber","Green"))))
H25: =IF(OR(A25="",C25=""),"",IF(E25<>"",MAX(0,E25-C25),MAX(0,TODAY()-C25))) | I25: =IF(OR(A25="",C25=""),"",IF(E25<>"",IF(E25<=C25,"Completed","Completed Late"),IF(TODAY()>C25,"Overdue","On Schedule"))) | J25: =IF(OR(A25="",C25=""),"",IF(E25<>"",IF(E25<=C25,"Green","Red"),IF(TODAY()>C25,"Red",IF(C25-TODAY()<=Config!$B$30,"Amber","Green"))))
H26: =IF(OR(A26="",C26=""),"",IF(E26<>"",MAX(0,E26-C26),MAX(0,TODAY()-C26))) | I26: =IF(OR(A26="",C26=""),"",IF(E26<>"",IF(E26<=C26,"Completed","Completed Late"),IF(TODAY()>C26,"Overdue","On Schedule"))) | J26: =IF(OR(A26="",C26=""),"",IF(E26<>"",IF(E26<=C26,"Green","Red"),IF(TODAY()>C26,"Red",IF(C26-TODAY()<=Config!$B$30,"Amber","Green"))))
H27: =IF(OR(A27="",C27=""),"",IF(E27<>"",MAX(0,E27-C27),MAX(0,TODAY()-C27))) | I27: =IF(OR(A27="",C27=""),"",IF(E27<>"",IF(E27<=C27,"Completed","Completed Late"),IF(TODAY()>C27,"Overdue","On Schedule"))) | J27: =IF(OR(A27="",C27=""),"",IF(E27<>"",IF(E27<=C27,"Green","Red"),IF(TODAY()>C27,"Red",IF(C27-TODAY()<=Config!$B$30,"Amber","Green"))))
H28: =IF(OR(A28="",C28=""),"",IF(E28<>"",MAX(0,E28-C28),MAX(0,TODAY()-C28))) | I28: =IF(OR(A28="",C28=""),"",IF(E28<>"",IF(E28<=C28,"Completed","Completed Late"),IF(TODAY()>C28,"Overdue","On Schedule"))) | J28: =IF(OR(A28="",C28=""),"",IF(E28<>"",IF(E28<=C28,"Green","Red"),IF(TODAY()>C28,"Red",IF(C28-TODAY()<=Config!$B$30,"Amber","Green"))))
... H305: =IF(OR(A305="",C305=""),"",IF(E305<>"",MAX(0,E305-C305),MAX(0,TODAY()-C305))) | I305: =IF(OR(A305="",C305=""),"",IF(E305<>"",IF(E305<=C305,"Completed","Completed Late"),IF(TODAY()>C305,"Overdue","On Schedule"))) | J305: =IF(OR(A305="",C305=""),"",IF(E305<>"",IF(E305<=C305,"Green","Red"),IF(TODAY()>C305,"Red",IF(C305-TODAY()<=Config!$B$30,"Amber","Green"))))

Sheet Readiness
A1: Readiness [SAMPLE DATA – illustrative]
A2: SIT readiness per topic per week: overall RAG, six readiness areas (RAG + note) and the road to Green.
A3: HOW TO FILL: each Friday add one row per topic still in preparation; pick RAG from the dropdowns and use short notes (Alt+Enter for new lines).
A5: Week Ending | B5: Topic | C5: Planned SIT Start | D5: Overall RAG | E5: Requirements & Arch Intent RAG | F5: Requirements & Arch Intent – Note | G5: Blockers RAG | H5: Blockers – Note | I5: Resources RAG | J5: Resources – Note | K5: Environments RAG | L5: Environments – Note | M5: Test Scripts & Test Data RAG | N5: Test Scripts & Test Data – Note | O5: Knowledge Transfer RAG | P5: Knowledge Transfer – Note | Q5: Road to Green | R5: Notes
A6: 46276 | B6: Self Assessment – Release 3 | C6: 46328 | D6: Green | E6: Green | F6: Requirements baselined and reviewed. | G6: Green | H6: N/A | I6: Green | J6: Resources in place. | K6: Green | L6: Test environment ready. | M6: Green | N6: Scripts and test data on plan. | O6: Green | P6: Knowledge transfer complete.
A7: 46276 | B7: Self Assessment – Digital Filing | C7: 46349 | D7: Green | E7: Green | F7: Requirements baselined and reviewed. | G7: Green | H7: N/A | I7: Green | J7: Resources in place. | K7: Green | L7: Test environment ready. | M7: Green | N7: Scripts and test data on plan. | O7: Green | P7: Knowledge transfer complete.
A8: 46283 | B8: Self Assessment – Release 3 | C8: 46328 | D8: Green | E8: Green | F8: Requirements baselined and reviewed. | G8: Green | H8: N/A | I8: Green | J8: Resources in place. | K8: Green | L8: Test environment ready. | M8: Green | N8: Scripts and test data on plan. | O8: Green | P8: Knowledge transfer complete.
A9: 46283 | B9: Self Assessment – Digital Filing | C9: 46349 | D9: Green | E9: Green | F9: Requirements baselined and reviewed. | G9: Green | H9: N/A | I9: Green | J9: Resources in place. | K9: Green | L9: Test environment ready. | M9: Green | N9: Scripts and test data on plan. | O9: Green | P9: Knowledge transfer complete.
A10: 46290 | B10: Self Assessment – Release 3 | C10: 46328 | D10: Green | E10: Green | F10: Requirements baselined and reviewed. | G10: Green | H10: N/A | I10: Green | J10: Resources in place. | K10: Green | L10: Test environment ready. | M10: Green | N10: Scripts and test data on plan. | O10: Green | P10: Knowledge transfer complete.
A11: 46290 | B11: Self Assessment – Digital Filing | C11: 46349 | D11: Green | E11: Green | F11: Requirements baselined and reviewed. | G11: Green | H11: N/A | I11: Green | J11: Resources in place. | K11: Green | L11: Test environment ready. | M11: Green | N11: Scripts and test data on plan. | O11: Green | P11: Knowledge transfer complete.
A12: 46297 | B12: Self Assessment – Release 3 | C12: 46328 | D12: Green | E12: Green | F12: Requirements baselined and reviewed. | G12: Green | H12: N/A | I12: Green | J12: Resources in place. | K12: Green | L12: Test environment ready. | M12: Green | N12: Scripts and test data on plan. | O12: Green | P12: Knowledge transfer complete.
A13: 46297 | B13: Self Assessment – Digital Filing | C13: 46349 | D13: Green | E13: Green | F13: Requirements baselined and reviewed. | G13: Green | H13: N/A | I13: Green | J13: Resources in place. | K13: Green | L13: Test environment ready. | M13: Green | N13: Scripts and test data on plan. | O13: Green | P13: Knowledge transfer complete.

Sheet Commentary
A1: Commentary [SAMPLE DATA – illustrative]
A2: Optional narrative per KPI per week (Key Highlights / Area of Concern / Actions Underway / Executive Commentary).
A3: HOW TO FILL: add a row for any KPI you want to explain this week (KPI from dropdown); separate bullets with Alt+Enter. RAG Override only if you disagree with the calculated RAG.
A5: Week Ending | B5: KPI | C5: Key Highlights | D5: Area of Concern | E5: Actions Underway | F5: Executive Commentary | G5: RAG Override | H5: Current Position Override | I5: Notes
A6: 46290 | B6: Overall | C6: Execution on plan and defects closed quickly; High and Medium risk coverage at or above target. | D6: None material. One low-priority defect is in triage. | E6: Continue Release 2 and Release 3 execution; keep daily defect triage. | F6: The portfolio remains Green. Test execution is progressing to plan, defect turnaround is well inside SLA, no milestones are overdue, and spend and forecast remain aligned to budget. | I6: SAMPLE

Sheet Resourcing
A1: Resourcing [SAMPLE DATA – illustrative]
A2: The team roster: role, name, organisation, allocation, dates and status.
A3: HOW TO FILL: add a row when someone joins or is planned; set End Date and Status = Left when they leave. Do not delete history.
A5: Role | B5: Name | C5: Organisation | D5: Allocation % | E5: Start Date | F5: End Date | G5: Status | H5: Notes
A6: Programme Test Manager | B6: TBC | C6: Delivery Partner | D6: 1 | E6: 46083 | G6: Active | H6: Name placeholder – SAMPLE.
A7: Test Manager | B7: TBC | C7: Delivery Partner | D7: 1 | E7: 46083 | G7: Active | H7: Name placeholder – SAMPLE.
A8: Test Lead | B8: TBC | C8: Delivery Partner | D8: 1 | E8: 46083 | G8: Active | H8: Name placeholder – SAMPLE.
A9: Senior Test Analyst 1 | B9: TBC | C9: Delivery Partner | D9: 1 | E9: 46090 | G9: Active | H9: Name placeholder – SAMPLE.
A10: Test Analyst 1 | B10: TBC | C10: Delivery Partner | D10: 1 | E10: 46090 | G10: Active | H10: Name placeholder – SAMPLE.
A11: Test Analyst 2 | B11: TBC | C11: Delivery Partner | D11: 1 | E11: 46090 | G11: Active | H11: Name placeholder – SAMPLE.

Sheet Demand_Forecast
A1: Demand_Forecast [SAMPLE DATA – illustrative]
A2: Forward view of Planned vs Available FTE by month (Month = first day of the month).
A3: HOW TO FILL: refresh monthly: one row per future month, Month entered as the 1st of the month.
A5: Month | B5: Planned FTE | C5: Available FTE | D5: Notes
A6: 46204 | B6: 6 | C6: 6 | D6: Capacity aligned to demand.
A7: 46235 | B7: 6 | C7: 6 | D7: Capacity aligned to demand.
A8: 46266 | B8: 6 | C8: 6 | D8: Capacity aligned to demand.
A9: 46296 | B9: 6 | C9: 6 | D9: Capacity aligned to demand.
